[2024-02-01T16:54:25.386+0000] {taskinstance.py:1159} INFO - Dependencies all met for dep_context=non-requeueable deps ti=<TaskInstance: calculating_gross_margin.calculating_gross_margin manual__2024-02-01T16:46:32.102278+00:00 [queued]>
[2024-02-01T16:54:25.403+0000] {taskinstance.py:1159} INFO - Dependencies all met for dep_context=requeueable deps ti=<TaskInstance: calculating_gross_margin.calculating_gross_margin manual__2024-02-01T16:46:32.102278+00:00 [queued]>
[2024-02-01T16:54:25.404+0000] {taskinstance.py:1361} INFO - Starting attempt 2 of 2
[2024-02-01T16:54:25.425+0000] {taskinstance.py:1382} INFO - Executing <Task(PythonOperator): calculating_gross_margin> on 2024-02-01 16:46:32.102278+00:00
[2024-02-01T16:54:25.620+0000] {standard_task_runner.py:57} INFO - Started process 560 to run task
[2024-02-01T16:54:25.629+0000] {standard_task_runner.py:84} INFO - Running: ['***', 'tasks', 'run', 'calculating_gross_margin', 'calculating_gross_margin', 'manual__2024-02-01T16:46:32.102278+00:00', '--job-id', '164', '--raw', '--subdir', 'DAGS_FOLDER/fundamental_data_pipeline.py', '--cfg-path', '/tmp/tmpkp26_iem']
[2024-02-01T16:54:25.633+0000] {standard_task_runner.py:85} INFO - Job 164: Subtask calculating_gross_margin
[2024-02-01T16:54:25.747+0000] {task_command.py:416} INFO - Running <TaskInstance: calculating_gross_margin.calculating_gross_margin manual__2024-02-01T16:46:32.102278+00:00 [running]> on host 617d7a1a687e
[2024-02-01T16:54:25.890+0000] {taskinstance.py:1662} INFO - Exporting env vars: AIRFLOW_CTX_DAG_EMAIL='gerardchurch133@outlook.com' AIRFLOW_CTX_DAG_OWNER='Airflow' AIRFLOW_CTX_DAG_ID='calculating_gross_margin' AIRFLOW_CTX_TASK_ID='calculating_gross_margin' AIRFLOW_CTX_EXECUTION_DATE='2024-02-01T16:46:32.102278+00:00' AIRFLOW_CTX_TRY_NUMBER='2' AIRFLOW_CTX_DAG_RUN_ID='manual__2024-02-01T16:46:32.102278+00:00'
[2024-02-01T16:54:46.440+0000] {_universal.py:514} INFO - Request URL: 'https://datalakeuksouth2311.table.core.windows.net/fundamentalsraw()?$filter=REDACTED'
Request method: 'GET'
Request headers:
    'x-ms-version': 'REDACTED'
    'DataServiceVersion': 'REDACTED'
    'Accept': 'application/json;odata=minimalmetadata'
    'x-ms-client-request-id': '9abfe6e0-c122-11ee-818e-0242ac120005'
    'x-ms-date': 'REDACTED'
    'Date': 'Thu, 01 Feb 2024 16:54:46 GMT'
    'User-Agent': 'azsdk-python-data-tables/12.5.0 Python/3.8.18 (Linux-5.10.16.3-microsoft-standard-WSL2-x86_64-with-glibc2.2.5)'
    'Authorization': 'REDACTED'
No body was attached to the request
[2024-02-01T16:54:47.027+0000] {_universal.py:550} INFO - Response status: 200
Response headers:
    'Cache-Control': 'no-cache'
    'Transfer-Encoding': 'chunked'
    'Content-Type': 'application/json;odata=minimalmetadata;streaming=true;charset=utf-8'
    'Server': 'Windows-Azure-Table/1.0 Microsoft-HTTPAPI/2.0'
    'x-ms-request-id': '5b0727fd-9002-0025-392f-552952000000'
    'x-ms-client-request-id': '9abfe6e0-c122-11ee-818e-0242ac120005'
    'x-ms-version': 'REDACTED'
    'X-Content-Type-Options': 'REDACTED'
    'Date': 'Thu, 01 Feb 2024 16:54:49 GMT'
[2024-02-01T16:54:53.221+0000] {_universal.py:514} INFO - Request URL: 'https://datalakeuksouth2311.table.core.windows.net/fundamentals()?$filter=REDACTED'
Request method: 'GET'
Request headers:
    'x-ms-version': 'REDACTED'
    'DataServiceVersion': 'REDACTED'
    'Accept': 'application/json;odata=minimalmetadata'
    'x-ms-client-request-id': '9ecaa748-c122-11ee-818e-0242ac120005'
    'x-ms-date': 'REDACTED'
    'Date': 'Thu, 01 Feb 2024 16:54:53 GMT'
    'User-Agent': 'azsdk-python-data-tables/12.5.0 Python/3.8.18 (Linux-5.10.16.3-microsoft-standard-WSL2-x86_64-with-glibc2.2.5)'
    'Authorization': 'REDACTED'
No body was attached to the request
[2024-02-01T16:54:53.251+0000] {_universal.py:550} INFO - Response status: 200
Response headers:
    'Cache-Control': 'no-cache'
    'Transfer-Encoding': 'chunked'
    'Content-Type': 'application/json;odata=minimalmetadata;streaming=true;charset=utf-8'
    'Server': 'Windows-Azure-Table/1.0 Microsoft-HTTPAPI/2.0'
    'x-ms-request-id': '5b0728b4-9002-0025-632f-552952000000'
    'x-ms-client-request-id': '9ecaa748-c122-11ee-818e-0242ac120005'
    'x-ms-version': 'REDACTED'
    'X-Content-Type-Options': 'REDACTED'
    'Date': 'Thu, 01 Feb 2024 16:54:55 GMT'
[2024-02-01T16:54:53.254+0000] {taskinstance.py:1937} ERROR - Task failed with exception
Traceback (most recent call last):
  File "/home/airflow/.local/lib/python3.8/site-packages/pandas/core/indexes/base.py", line 3653, in get_loc
    return self._engine.get_loc(casted_key)
  File "pandas/_libs/index.pyx", line 147, in pandas._libs.index.IndexEngine.get_loc
  File "pandas/_libs/index.pyx", line 176, in pandas._libs.index.IndexEngine.get_loc
  File "pandas/_libs/hashtable_class_helper.pxi", line 7080, in pandas._libs.hashtable.PyObjectHashTable.get_item
  File "pandas/_libs/hashtable_class_helper.pxi", line 7088, in pandas._libs.hashtable.PyObjectHashTable.get_item
KeyError: 'RowKey'

The above exception was the direct cause of the following exception:

Traceback (most recent call last):
  File "/home/airflow/.local/lib/python3.8/site-packages/airflow/operators/python.py", line 192, in execute
    return_value = self.execute_callable()
  File "/home/airflow/.local/lib/python3.8/site-packages/airflow/operators/python.py", line 209, in execute_callable
    return self.python_callable(*self.op_args, **self.op_kwargs)
  File "/opt/airflow/dags/fundamental_data_pipeline.py", line 90, in get_gross_margin
    new_core_entities = fundamentals_raw[~fundamentals_raw['RowKey'].isin(fundamentals_core['RowKey'].tolist())]
  File "/home/airflow/.local/lib/python3.8/site-packages/pandas/core/frame.py", line 3761, in __getitem__
    indexer = self.columns.get_loc(key)
  File "/home/airflow/.local/lib/python3.8/site-packages/pandas/core/indexes/base.py", line 3655, in get_loc
    raise KeyError(key) from err
KeyError: 'RowKey'
[2024-02-01T16:54:53.315+0000] {taskinstance.py:1400} INFO - Marking task as FAILED. dag_id=calculating_gross_margin, task_id=calculating_gross_margin, execution_date=20240201T164632, start_date=20240201T165425, end_date=20240201T165453
[2024-02-01T16:54:53.352+0000] {warnings.py:109} WARNING - /home/***/.local/lib/python3.8/site-packages/***/utils/email.py:154: RemovedInAirflow3Warning: Fetching SMTP credentials from configuration variables will be deprecated in a future release. Please set credentials using a connection instead.
  send_mime_email(e_from=mail_from, e_to=recipients, mime_msg=msg, conn_id=conn_id, dryrun=dryrun)

[2024-02-01T16:54:53.353+0000] {email.py:270} INFO - Email alerting: attempt 1
[2024-02-01T16:54:53.915+0000] {email.py:281} INFO - Sent an alert email to ['gerardchurch133@outlook.com']
[2024-02-01T16:54:54.034+0000] {email.py:270} INFO - Email alerting: attempt 1
[2024-02-01T16:54:54.336+0000] {email.py:281} INFO - Sent an alert email to ['gerardchurch133@outlook.com']
[2024-02-01T16:54:54.452+0000] {taskinstance.py:2007} ERROR - Failed to send email to: gerardchurch133@outlook.com
Traceback (most recent call last):
  File "/home/airflow/.local/lib/python3.8/site-packages/pandas/core/indexes/base.py", line 3653, in get_loc
    return self._engine.get_loc(casted_key)
  File "pandas/_libs/index.pyx", line 147, in pandas._libs.index.IndexEngine.get_loc
  File "pandas/_libs/index.pyx", line 176, in pandas._libs.index.IndexEngine.get_loc
  File "pandas/_libs/hashtable_class_helper.pxi", line 7080, in pandas._libs.hashtable.PyObjectHashTable.get_item
  File "pandas/_libs/hashtable_class_helper.pxi", line 7088, in pandas._libs.hashtable.PyObjectHashTable.get_item
KeyError: 'RowKey'

The above exception was the direct cause of the following exception:

Traceback (most recent call last):
  File "/home/airflow/.local/lib/python3.8/site-packages/airflow/models/taskinstance.py", line 1518, in _run_raw_task
    self._execute_task_with_callbacks(context, test_mode, session=session)
  File "/home/airflow/.local/lib/python3.8/site-packages/airflow/models/taskinstance.py", line 1681, in _execute_task_with_callbacks
    result = self._execute_task(context, task_orig)
  File "/home/airflow/.local/lib/python3.8/site-packages/airflow/models/taskinstance.py", line 1744, in _execute_task
    result = execute_callable(context=context, **execute_callable_kwargs)
  File "/home/airflow/.local/lib/python3.8/site-packages/airflow/operators/python.py", line 192, in execute
    return_value = self.execute_callable()
  File "/home/airflow/.local/lib/python3.8/site-packages/airflow/operators/python.py", line 209, in execute_callable
    return self.python_callable(*self.op_args, **self.op_kwargs)
  File "/opt/airflow/dags/fundamental_data_pipeline.py", line 90, in get_gross_margin
    new_core_entities = fundamentals_raw[~fundamentals_raw['RowKey'].isin(fundamentals_core['RowKey'].tolist())]
  File "/home/airflow/.local/lib/python3.8/site-packages/pandas/core/frame.py", line 3761, in __getitem__
    indexer = self.columns.get_loc(key)
  File "/home/airflow/.local/lib/python3.8/site-packages/pandas/core/indexes/base.py", line 3655, in get_loc
    raise KeyError(key) from err
KeyError: 'RowKey'

During handling of the above exception, another exception occurred:

Traceback (most recent call last):
  File "/home/airflow/.local/lib/python3.8/site-packages/airflow/models/taskinstance.py", line 2420, in email_alert
    send_email(task.email, subject, html_content)
  File "/home/airflow/.local/lib/python3.8/site-packages/airflow/utils/email.py", line 80, in send_email
    return backend(
  File "/home/airflow/.local/lib/python3.8/site-packages/airflow/utils/email.py", line 154, in send_email_smtp
    send_mime_email(e_from=mail_from, e_to=recipients, mime_msg=msg, conn_id=conn_id, dryrun=dryrun)
  File "/home/airflow/.local/lib/python3.8/site-packages/airflow/utils/email.py", line 282, in send_mime_email
    smtp_conn.sendmail(e_from, e_to, mime_msg.as_string())
  File "/usr/local/lib/python3.8/smtplib.py", line 906, in sendmail
    raise SMTPDataError(code, resp)
smtplib.SMTPDataError: (432, b'4.3.2 Concurrent connections limit exceeded. Visit https://aka.ms/concurrent_sending for more information. [Hostname=DB9P193MB1849.EURP193.PROD.OUTLOOK.COM]')

During handling of the above exception, another exception occurred:

Traceback (most recent call last):
  File "/home/airflow/.local/lib/python3.8/site-packages/airflow/models/taskinstance.py", line 2005, in handle_failure
    self.email_alert(error, task)
  File "/home/airflow/.local/lib/python3.8/site-packages/airflow/models/taskinstance.py", line 2422, in email_alert
    send_email(task.email, subject, html_content_err)
  File "/home/airflow/.local/lib/python3.8/site-packages/airflow/utils/email.py", line 80, in send_email
    return backend(
  File "/home/airflow/.local/lib/python3.8/site-packages/airflow/utils/email.py", line 154, in send_email_smtp
    send_mime_email(e_from=mail_from, e_to=recipients, mime_msg=msg, conn_id=conn_id, dryrun=dryrun)
  File "/home/airflow/.local/lib/python3.8/site-packages/airflow/utils/email.py", line 282, in send_mime_email
    smtp_conn.sendmail(e_from, e_to, mime_msg.as_string())
  File "/usr/local/lib/python3.8/smtplib.py", line 906, in sendmail
    raise SMTPDataError(code, resp)
smtplib.SMTPDataError: (432, b'4.3.2 Concurrent connections limit exceeded. Visit https://aka.ms/concurrent_sending for more information. [Hostname=DB9P193MB1849.EURP193.PROD.OUTLOOK.COM]')
[2024-02-01T16:54:54.483+0000] {standard_task_runner.py:104} ERROR - Failed to execute job 164 for task calculating_gross_margin ('RowKey'; 560)
[2024-02-01T16:54:54.534+0000] {local_task_job_runner.py:228} INFO - Task exited with return code 1
[2024-02-01T16:54:54.580+0000] {taskinstance.py:2778} INFO - 0 downstream tasks scheduled from follow-on schedule check
