[2024-01-31T21:19:10.522+0000] {taskinstance.py:1159} INFO - Dependencies all met for dep_context=non-requeueable deps ti=<TaskInstance: calculating_gross_margin.downloading_fundamentals scheduled__2024-01-30T00:00:00+00:00 [queued]>
[2024-01-31T21:19:10.542+0000] {taskinstance.py:1159} INFO - Dependencies all met for dep_context=requeueable deps ti=<TaskInstance: calculating_gross_margin.downloading_fundamentals scheduled__2024-01-30T00:00:00+00:00 [queued]>
[2024-01-31T21:19:10.543+0000] {taskinstance.py:1361} INFO - Starting attempt 2 of 2
[2024-01-31T21:19:10.562+0000] {taskinstance.py:1382} INFO - Executing <Task(PythonOperator): downloading_fundamentals> on 2024-01-30 00:00:00+00:00
[2024-01-31T21:19:10.651+0000] {standard_task_runner.py:57} INFO - Started process 230 to run task
[2024-01-31T21:19:10.662+0000] {standard_task_runner.py:84} INFO - Running: ['***', 'tasks', 'run', 'calculating_gross_margin', 'downloading_fundamentals', 'scheduled__2024-01-30T00:00:00+00:00', '--job-id', '102', '--raw', '--subdir', 'DAGS_FOLDER/fundamental_data_pipeline.py', '--cfg-path', '/tmp/tmpubvaa798']
[2024-01-31T21:19:10.668+0000] {standard_task_runner.py:85} INFO - Job 102: Subtask downloading_fundamentals
[2024-01-31T21:19:10.768+0000] {task_command.py:416} INFO - Running <TaskInstance: calculating_gross_margin.downloading_fundamentals scheduled__2024-01-30T00:00:00+00:00 [running]> on host 66a208939447
[2024-01-31T21:19:10.901+0000] {taskinstance.py:1662} INFO - Exporting env vars: AIRFLOW_CTX_DAG_EMAIL='gerardchurch133@outlook.com' AIRFLOW_CTX_DAG_OWNER='Airflow' AIRFLOW_CTX_DAG_ID='calculating_gross_margin' AIRFLOW_CTX_TASK_ID='downloading_fundamentals' AIRFLOW_CTX_EXECUTION_DATE='2024-01-30T00:00:00+00:00' AIRFLOW_CTX_TRY_NUMBER='2' AIRFLOW_CTX_DAG_RUN_ID='scheduled__2024-01-30T00:00:00+00:00'
[2024-01-31T21:19:14.087+0000] {_universal.py:511} INFO - Request URL: 'https://datalakeuksouth2311.table.core.windows.net/fundamentalsraw/fundamentalsraw'
Request method: 'POST'
Request headers:
    'Content-Type': 'application/json;odata=nometadata'
    'Content-Length': '18176'
    'x-ms-version': 'REDACTED'
    'DataServiceVersion': 'REDACTED'
    'Accept': 'application/json;odata=minimalmetadata'
    'x-ms-client-request-id': '62311dca-c07e-11ee-9b06-0242ac150007'
    'x-ms-date': 'REDACTED'
    'Date': 'Wed, 31 Jan 2024 21:19:14 GMT'
    'User-Agent': 'azsdk-python-data-tables/12.5.0 Python/3.8.18 (Linux-5.10.16.3-microsoft-standard-WSL2-x86_64-with-glibc2.2.5)'
    'Authorization': 'REDACTED'
A body is sent with the request
[2024-01-31T21:19:14.298+0000] {_universal.py:550} INFO - Response status: 409
Response headers:
    'Cache-Control': 'no-cache'
    'Transfer-Encoding': 'chunked'
    'Content-Type': 'application/json;odata=minimalmetadata;streaming=true;charset=utf-8'
    'Server': 'Windows-Azure-Table/1.0 Microsoft-HTTPAPI/2.0'
    'x-ms-request-id': '4e1e5a87-f002-006e-118b-54d501000000'
    'x-ms-client-request-id': '62311dca-c07e-11ee-9b06-0242ac150007'
    'x-ms-version': 'REDACTED'
    'X-Content-Type-Options': 'REDACTED'
    'Date': 'Wed, 31 Jan 2024 21:19:15 GMT'
[2024-01-31T21:19:14.303+0000] {taskinstance.py:1937} ERROR - Task failed with exception
Traceback (most recent call last):
  File "/home/airflow/.local/lib/python3.8/site-packages/airflow/operators/python.py", line 192, in execute
    return_value = self.execute_callable()
  File "/home/airflow/.local/lib/python3.8/site-packages/airflow/operators/python.py", line 209, in execute_callable
    return self.python_callable(*self.op_args, **self.op_kwargs)
  File "/opt/airflow/dags/fundamental_data_pipeline.py", line 61, in get_fundamental_data
    [fundamentals_raw_table.create_entity(entity) for entity in entities]
  File "/opt/airflow/dags/fundamental_data_pipeline.py", line 61, in <listcomp>
    [fundamentals_raw_table.create_entity(entity) for entity in entities]
  File "/home/airflow/.local/lib/python3.8/site-packages/azure/core/tracing/decorator.py", line 78, in wrapper_use_tracer
    return func(*args, **kwargs)
  File "/home/airflow/.local/lib/python3.8/site-packages/azure/data/tables/_table_client.py", line 405, in create_entity
    raise error
  File "/home/airflow/.local/lib/python3.8/site-packages/azure/data/tables/_table_client.py", line 393, in create_entity
    self._client.table.insert_entity(
  File "/home/airflow/.local/lib/python3.8/site-packages/azure/core/tracing/decorator.py", line 78, in wrapper_use_tracer
    return func(*args, **kwargs)
  File "/home/airflow/.local/lib/python3.8/site-packages/azure/data/tables/_generated/operations/_operations.py", line 1703, in insert_entity
    map_error(status_code=response.status_code, response=response, error_map=error_map)
  File "/home/airflow/.local/lib/python3.8/site-packages/azure/core/exceptions.py", line 165, in map_error
    raise error
azure.core.exceptions.ResourceExistsError: Operation returned an invalid status 'Conflict'
Content: {"odata.error":{"code":"EntityAlreadyExists","message":{"lang":"en-US","value":"The specified entity already exists.\nRequestId:4e1e5a87-f002-006e-118b-54d501000000\nTime:2024-01-31T21:19:16.1353989Z"}}}
[2024-01-31T21:19:14.332+0000] {taskinstance.py:1400} INFO - Marking task as FAILED. dag_id=calculating_gross_margin, task_id=downloading_fundamentals, execution_date=20240130T000000, start_date=20240131T211910, end_date=20240131T211914
[2024-01-31T21:19:14.364+0000] {warnings.py:109} WARNING - /home/***/.local/lib/python3.8/site-packages/***/utils/email.py:154: RemovedInAirflow3Warning: Fetching SMTP credentials from configuration variables will be deprecated in a future release. Please set credentials using a connection instead.
  send_mime_email(e_from=mail_from, e_to=recipients, mime_msg=msg, conn_id=conn_id, dryrun=dryrun)

[2024-01-31T21:19:14.365+0000] {configuration.py:1050} WARNING - section/key [smtp/smtp_user] not found in config
[2024-01-31T21:19:14.365+0000] {email.py:270} INFO - Email alerting: attempt 1
[2024-01-31T21:19:14.381+0000] {configuration.py:1050} WARNING - section/key [smtp/smtp_user] not found in config
[2024-01-31T21:19:14.381+0000] {email.py:270} INFO - Email alerting: attempt 1
[2024-01-31T21:19:14.382+0000] {taskinstance.py:2007} ERROR - Failed to send email to: gerardchurch133@outlook.com
Traceback (most recent call last):
  File "/home/airflow/.local/lib/python3.8/site-packages/airflow/models/taskinstance.py", line 1518, in _run_raw_task
    self._execute_task_with_callbacks(context, test_mode, session=session)
  File "/home/airflow/.local/lib/python3.8/site-packages/airflow/models/taskinstance.py", line 1681, in _execute_task_with_callbacks
    result = self._execute_task(context, task_orig)
  File "/home/airflow/.local/lib/python3.8/site-packages/airflow/models/taskinstance.py", line 1744, in _execute_task
    result = execute_callable(context=context, **execute_callable_kwargs)
  File "/home/airflow/.local/lib/python3.8/site-packages/airflow/operators/python.py", line 192, in execute
    return_value = self.execute_callable()
  File "/home/airflow/.local/lib/python3.8/site-packages/airflow/operators/python.py", line 209, in execute_callable
    return self.python_callable(*self.op_args, **self.op_kwargs)
  File "/opt/airflow/dags/fundamental_data_pipeline.py", line 61, in get_fundamental_data
    [fundamentals_raw_table.create_entity(entity) for entity in entities]
  File "/opt/airflow/dags/fundamental_data_pipeline.py", line 61, in <listcomp>
    [fundamentals_raw_table.create_entity(entity) for entity in entities]
  File "/home/airflow/.local/lib/python3.8/site-packages/azure/core/tracing/decorator.py", line 78, in wrapper_use_tracer
    return func(*args, **kwargs)
  File "/home/airflow/.local/lib/python3.8/site-packages/azure/data/tables/_table_client.py", line 405, in create_entity
    raise error
  File "/home/airflow/.local/lib/python3.8/site-packages/azure/data/tables/_table_client.py", line 393, in create_entity
    self._client.table.insert_entity(
  File "/home/airflow/.local/lib/python3.8/site-packages/azure/core/tracing/decorator.py", line 78, in wrapper_use_tracer
    return func(*args, **kwargs)
  File "/home/airflow/.local/lib/python3.8/site-packages/azure/data/tables/_generated/operations/_operations.py", line 1703, in insert_entity
    map_error(status_code=response.status_code, response=response, error_map=error_map)
  File "/home/airflow/.local/lib/python3.8/site-packages/azure/core/exceptions.py", line 165, in map_error
    raise error
azure.core.exceptions.ResourceExistsError: Operation returned an invalid status 'Conflict'
Content: {"odata.error":{"code":"EntityAlreadyExists","message":{"lang":"en-US","value":"The specified entity already exists.\nRequestId:4e1e5a87-f002-006e-118b-54d501000000\nTime:2024-01-31T21:19:16.1353989Z"}}}

During handling of the above exception, another exception occurred:

Traceback (most recent call last):
  File "/home/airflow/.local/lib/python3.8/site-packages/airflow/models/taskinstance.py", line 2420, in email_alert
    send_email(task.email, subject, html_content)
  File "/home/airflow/.local/lib/python3.8/site-packages/airflow/utils/email.py", line 80, in send_email
    return backend(
  File "/home/airflow/.local/lib/python3.8/site-packages/airflow/utils/email.py", line 154, in send_email_smtp
    send_mime_email(e_from=mail_from, e_to=recipients, mime_msg=msg, conn_id=conn_id, dryrun=dryrun)
  File "/home/airflow/.local/lib/python3.8/site-packages/airflow/utils/email.py", line 272, in send_mime_email
    smtp_conn = _get_smtp_connection(smtp_host, smtp_port, smtp_timeout, smtp_ssl)
  File "/home/airflow/.local/lib/python3.8/site-packages/airflow/utils/email.py", line 316, in _get_smtp_connection
    return smtplib.SMTP(host=host, port=port, timeout=timeout)
  File "/usr/local/lib/python3.8/smtplib.py", line 255, in __init__
    (code, msg) = self.connect(host, port)
  File "/usr/local/lib/python3.8/smtplib.py", line 339, in connect
    self.sock = self._get_socket(host, port, self.timeout)
  File "/usr/local/lib/python3.8/smtplib.py", line 310, in _get_socket
    return socket.create_connection((host, port), timeout,
  File "/usr/local/lib/python3.8/socket.py", line 808, in create_connection
    raise err
  File "/usr/local/lib/python3.8/socket.py", line 796, in create_connection
    sock.connect(sa)
OSError: [Errno 99] Cannot assign requested address

During handling of the above exception, another exception occurred:

Traceback (most recent call last):
  File "/home/airflow/.local/lib/python3.8/site-packages/airflow/models/taskinstance.py", line 2005, in handle_failure
    self.email_alert(error, task)
  File "/home/airflow/.local/lib/python3.8/site-packages/airflow/models/taskinstance.py", line 2422, in email_alert
    send_email(task.email, subject, html_content_err)
  File "/home/airflow/.local/lib/python3.8/site-packages/airflow/utils/email.py", line 80, in send_email
    return backend(
  File "/home/airflow/.local/lib/python3.8/site-packages/airflow/utils/email.py", line 154, in send_email_smtp
    send_mime_email(e_from=mail_from, e_to=recipients, mime_msg=msg, conn_id=conn_id, dryrun=dryrun)
  File "/home/airflow/.local/lib/python3.8/site-packages/airflow/utils/email.py", line 272, in send_mime_email
    smtp_conn = _get_smtp_connection(smtp_host, smtp_port, smtp_timeout, smtp_ssl)
  File "/home/airflow/.local/lib/python3.8/site-packages/airflow/utils/email.py", line 316, in _get_smtp_connection
    return smtplib.SMTP(host=host, port=port, timeout=timeout)
  File "/usr/local/lib/python3.8/smtplib.py", line 255, in __init__
    (code, msg) = self.connect(host, port)
  File "/usr/local/lib/python3.8/smtplib.py", line 339, in connect
    self.sock = self._get_socket(host, port, self.timeout)
  File "/usr/local/lib/python3.8/smtplib.py", line 310, in _get_socket
    return socket.create_connection((host, port), timeout,
  File "/usr/local/lib/python3.8/socket.py", line 808, in create_connection
    raise err
  File "/usr/local/lib/python3.8/socket.py", line 796, in create_connection
    sock.connect(sa)
OSError: [Errno 99] Cannot assign requested address
[2024-01-31T21:19:14.423+0000] {standard_task_runner.py:104} ERROR - Failed to execute job 102 for task downloading_fundamentals (Operation returned an invalid status 'Conflict'
Content: {"odata.error":{"code":"EntityAlreadyExists","message":{"lang":"en-US","value":"The specified entity already exists.\nRequestId:4e1e5a87-f002-006e-118b-54d501000000\nTime:2024-01-31T21:19:16.1353989Z"}}}; 230)
[2024-01-31T21:19:14.454+0000] {local_task_job_runner.py:228} INFO - Task exited with return code 1
[2024-01-31T21:19:14.500+0000] {taskinstance.py:2778} INFO - 0 downstream tasks scheduled from follow-on schedule check
