[2024-01-30T23:08:40.667+0000] {taskinstance.py:1159} INFO - Dependencies all met for dep_context=non-requeueable deps ti=<TaskInstance: downloading_fundamentals.downloading_fundamentals manual__2024-01-30T23:08:30.681308+00:00 [queued]>
[2024-01-30T23:08:40.676+0000] {taskinstance.py:1159} INFO - Dependencies all met for dep_context=requeueable deps ti=<TaskInstance: downloading_fundamentals.downloading_fundamentals manual__2024-01-30T23:08:30.681308+00:00 [queued]>
[2024-01-30T23:08:40.677+0000] {taskinstance.py:1361} INFO - Starting attempt 1 of 2
[2024-01-30T23:08:40.690+0000] {taskinstance.py:1382} INFO - Executing <Task(PythonOperator): downloading_fundamentals> on 2024-01-30 23:08:30.681308+00:00
[2024-01-30T23:08:40.695+0000] {standard_task_runner.py:57} INFO - Started process 290 to run task
[2024-01-30T23:08:40.699+0000] {standard_task_runner.py:84} INFO - Running: ['***', 'tasks', 'run', 'downloading_fundamentals', 'downloading_fundamentals', 'manual__2024-01-30T23:08:30.681308+00:00', '--job-id', '77', '--raw', '--subdir', 'DAGS_FOLDER/fundamental_data_pipeline.py', '--cfg-path', '/tmp/tmpi1adusat']
[2024-01-30T23:08:40.702+0000] {standard_task_runner.py:85} INFO - Job 77: Subtask downloading_fundamentals
[2024-01-30T23:08:40.750+0000] {task_command.py:416} INFO - Running <TaskInstance: downloading_fundamentals.downloading_fundamentals manual__2024-01-30T23:08:30.681308+00:00 [running]> on host f7d0f38ec0f6
[2024-01-30T23:08:40.816+0000] {taskinstance.py:1662} INFO - Exporting env vars: AIRFLOW_CTX_DAG_EMAIL='gerardchurch133@gmail.com' AIRFLOW_CTX_DAG_OWNER='Airflow' AIRFLOW_CTX_DAG_ID='downloading_fundamentals' AIRFLOW_CTX_TASK_ID='downloading_fundamentals' AIRFLOW_CTX_EXECUTION_DATE='2024-01-30T23:08:30.681308+00:00' AIRFLOW_CTX_TRY_NUMBER='1' AIRFLOW_CTX_DAG_RUN_ID='manual__2024-01-30T23:08:30.681308+00:00'
[2024-01-30T23:08:42.234+0000] {_universal.py:511} INFO - Request URL: 'https://datalakeuksouth2311.table.core.windows.net/fundamentalsraw/fundamentalsraw'
Request method: 'POST'
Request headers:
    'Content-Type': 'application/json;odata=nometadata'
    'Content-Length': '18176'
    'x-ms-version': 'REDACTED'
    'DataServiceVersion': 'REDACTED'
    'Accept': 'application/json;odata=minimalmetadata'
    'x-ms-client-request-id': '82b31cb6-bfc4-11ee-a53f-0242ac120006'
    'x-ms-date': 'REDACTED'
    'Date': 'Tue, 30 Jan 2024 23:08:42 GMT'
    'User-Agent': 'azsdk-python-data-tables/12.5.0 Python/3.8.18 (Linux-5.10.16.3-microsoft-standard-WSL2-x86_64-with-glibc2.2.5)'
    'Authorization': 'REDACTED'
A body is sent with the request
[2024-01-30T23:08:42.365+0000] {_universal.py:550} INFO - Response status: 409
Response headers:
    'Cache-Control': 'no-cache'
    'Transfer-Encoding': 'chunked'
    'Content-Type': 'application/json;odata=minimalmetadata;streaming=true;charset=utf-8'
    'Server': 'Windows-Azure-Table/1.0 Microsoft-HTTPAPI/2.0'
    'x-ms-request-id': '6437cb3b-c002-0017-37d1-532925000000'
    'x-ms-client-request-id': '82b31cb6-bfc4-11ee-a53f-0242ac120006'
    'x-ms-version': 'REDACTED'
    'X-Content-Type-Options': 'REDACTED'
    'Date': 'Tue, 30 Jan 2024 23:08:44 GMT'
[2024-01-30T23:08:42.369+0000] {taskinstance.py:1937} ERROR - Task failed with exception
Traceback (most recent call last):
  File "/home/airflow/.local/lib/python3.8/site-packages/airflow/operators/python.py", line 192, in execute
    return_value = self.execute_callable()
  File "/home/airflow/.local/lib/python3.8/site-packages/airflow/operators/python.py", line 209, in execute_callable
    return self.python_callable(*self.op_args, **self.op_kwargs)
  File "/opt/airflow/dags/fundamental_data_pipeline.py", line 61, in get_fundamental_data
    [fundamentals_raw_table.create_entity(entity) for entity in entities]
  File "/opt/airflow/dags/fundamental_data_pipeline.py", line 61, in <listcomp>
    [fundamentals_raw_table.create_entity(entity) for entity in entities]
  File "/home/airflow/.local/lib/python3.8/site-packages/azure/core/tracing/decorator.py", line 78, in wrapper_use_tracer
    return func(*args, **kwargs)
  File "/home/airflow/.local/lib/python3.8/site-packages/azure/data/tables/_table_client.py", line 405, in create_entity
    raise error
  File "/home/airflow/.local/lib/python3.8/site-packages/azure/data/tables/_table_client.py", line 393, in create_entity
    self._client.table.insert_entity(
  File "/home/airflow/.local/lib/python3.8/site-packages/azure/core/tracing/decorator.py", line 78, in wrapper_use_tracer
    return func(*args, **kwargs)
  File "/home/airflow/.local/lib/python3.8/site-packages/azure/data/tables/_generated/operations/_operations.py", line 1703, in insert_entity
    map_error(status_code=response.status_code, response=response, error_map=error_map)
  File "/home/airflow/.local/lib/python3.8/site-packages/azure/core/exceptions.py", line 165, in map_error
    raise error
azure.core.exceptions.ResourceExistsError: Operation returned an invalid status 'Conflict'
Content: {"odata.error":{"code":"EntityAlreadyExists","message":{"lang":"en-US","value":"The specified entity already exists.\nRequestId:6437cb3b-c002-0017-37d1-532925000000\nTime:2024-01-30T23:08:45.1485581Z"}}}
[2024-01-30T23:08:42.387+0000] {taskinstance.py:1400} INFO - Marking task as UP_FOR_RETRY. dag_id=downloading_fundamentals, task_id=downloading_fundamentals, execution_date=20240130T230830, start_date=20240130T230840, end_date=20240130T230842
[2024-01-30T23:08:42.401+0000] {standard_task_runner.py:104} ERROR - Failed to execute job 77 for task downloading_fundamentals (Operation returned an invalid status 'Conflict'
Content: {"odata.error":{"code":"EntityAlreadyExists","message":{"lang":"en-US","value":"The specified entity already exists.\nRequestId:6437cb3b-c002-0017-37d1-532925000000\nTime:2024-01-30T23:08:45.1485581Z"}}}; 290)
[2024-01-30T23:08:42.438+0000] {local_task_job_runner.py:228} INFO - Task exited with return code 1
[2024-01-30T23:08:42.460+0000] {taskinstance.py:2778} INFO - 0 downstream tasks scheduled from follow-on schedule check
