[2024-02-08T00:00:04.611+0000] {taskinstance.py:1159} INFO - Dependencies all met for dep_context=non-requeueable deps ti=<TaskInstance: calculating_gross_margin.checking_api_for_data scheduled__2024-02-07T00:00:00+00:00 [queued]>
[2024-02-08T00:00:04.621+0000] {taskinstance.py:1159} INFO - Dependencies all met for dep_context=requeueable deps ti=<TaskInstance: calculating_gross_margin.checking_api_for_data scheduled__2024-02-07T00:00:00+00:00 [queued]>
[2024-02-08T00:00:04.622+0000] {taskinstance.py:1361} INFO - Starting attempt 1 of 2
[2024-02-08T00:00:04.637+0000] {taskinstance.py:1382} INFO - Executing <Task(HttpSensor): checking_api_for_data> on 2024-02-07 00:00:00+00:00
[2024-02-08T00:00:04.648+0000] {standard_task_runner.py:57} INFO - Started process 8775 to run task
[2024-02-08T00:00:04.652+0000] {standard_task_runner.py:84} INFO - Running: ['***', 'tasks', 'run', 'calculating_gross_margin', 'checking_api_for_data', 'scheduled__2024-02-07T00:00:00+00:00', '--job-id', '188', '--raw', '--subdir', 'DAGS_FOLDER/fundamental_data_pipeline.py', '--cfg-path', '/tmp/tmpto_oxp56']
[2024-02-08T00:00:04.656+0000] {standard_task_runner.py:85} INFO - Job 188: Subtask checking_api_for_data
[2024-02-08T00:00:04.713+0000] {task_command.py:416} INFO - Running <TaskInstance: calculating_gross_margin.checking_api_for_data scheduled__2024-02-07T00:00:00+00:00 [running]> on host 617d7a1a687e
[2024-02-08T00:00:04.796+0000] {taskinstance.py:1662} INFO - Exporting env vars: AIRFLOW_CTX_DAG_EMAIL='gerardchurch133@outlook.com' AIRFLOW_CTX_DAG_OWNER='Airflow' AIRFLOW_CTX_DAG_ID='calculating_gross_margin' AIRFLOW_CTX_TASK_ID='checking_api_for_data' AIRFLOW_CTX_EXECUTION_DATE='2024-02-07T00:00:00+00:00' AIRFLOW_CTX_TRY_NUMBER='1' AIRFLOW_CTX_DAG_RUN_ID='scheduled__2024-02-07T00:00:00+00:00'
[2024-02-08T00:00:04.798+0000] {http.py:130} INFO - Poking: symbols/get-financials
[2024-02-08T00:00:04.808+0000] {base.py:73} INFO - Using connection ID 'rapid_api' for task execution.
[2024-02-08T00:00:14.821+0000] {http.py:221} WARNING - HTTPSConnectionPool(host='seeking-alpha.p.rapidapi.com', port=443): Max retries exceeded with url: /symbols/get-financials?symbol=aapl&target_currency=USD&period_type=annual&statement_type=income-statement (Caused by NewConnectionError('<urllib3.connection.HTTPSConnection object at 0x7ff792bb86a0>: Failed to establish a new connection: [Errno -3] Temporary failure in name resolution')) Tenacity will retry to execute the operation
[2024-02-08T00:00:14.822+0000] {taskinstance.py:1937} ERROR - Task failed with exception
Traceback (most recent call last):
  File "/home/airflow/.local/lib/python3.8/site-packages/urllib3/connection.py", line 174, in _new_conn
    conn = connection.create_connection(
  File "/home/airflow/.local/lib/python3.8/site-packages/urllib3/util/connection.py", line 72, in create_connection
    for res in socket.getaddrinfo(host, port, family, socket.SOCK_STREAM):
  File "/usr/local/lib/python3.8/socket.py", line 918, in getaddrinfo
    for res in _socket.getaddrinfo(host, port, family, type, proto, flags):
socket.gaierror: [Errno -3] Temporary failure in name resolution

During handling of the above exception, another exception occurred:

Traceback (most recent call last):
  File "/home/airflow/.local/lib/python3.8/site-packages/urllib3/connectionpool.py", line 715, in urlopen
    httplib_response = self._make_request(
  File "/home/airflow/.local/lib/python3.8/site-packages/urllib3/connectionpool.py", line 404, in _make_request
    self._validate_conn(conn)
  File "/home/airflow/.local/lib/python3.8/site-packages/urllib3/connectionpool.py", line 1058, in _validate_conn
    conn.connect()
  File "/home/airflow/.local/lib/python3.8/site-packages/urllib3/connection.py", line 363, in connect
    self.sock = conn = self._new_conn()
  File "/home/airflow/.local/lib/python3.8/site-packages/urllib3/connection.py", line 186, in _new_conn
    raise NewConnectionError(
urllib3.exceptions.NewConnectionError: <urllib3.connection.HTTPSConnection object at 0x7ff792bb86a0>: Failed to establish a new connection: [Errno -3] Temporary failure in name resolution

During handling of the above exception, another exception occurred:

Traceback (most recent call last):
  File "/home/airflow/.local/lib/python3.8/site-packages/requests/adapters.py", line 486, in send
    resp = conn.urlopen(
  File "/home/airflow/.local/lib/python3.8/site-packages/urllib3/connectionpool.py", line 799, in urlopen
    retries = retries.increment(
  File "/home/airflow/.local/lib/python3.8/site-packages/urllib3/util/retry.py", line 592, in increment
    raise MaxRetryError(_pool, url, error or ResponseError(cause))
urllib3.exceptions.MaxRetryError: HTTPSConnectionPool(host='seeking-alpha.p.rapidapi.com', port=443): Max retries exceeded with url: /symbols/get-financials?symbol=aapl&target_currency=USD&period_type=annual&statement_type=income-statement (Caused by NewConnectionError('<urllib3.connection.HTTPSConnection object at 0x7ff792bb86a0>: Failed to establish a new connection: [Errno -3] Temporary failure in name resolution'))

During handling of the above exception, another exception occurred:

Traceback (most recent call last):
  File "/home/airflow/.local/lib/python3.8/site-packages/airflow/sensors/base.py", line 257, in execute
    raise e
  File "/home/airflow/.local/lib/python3.8/site-packages/airflow/sensors/base.py", line 239, in execute
    poke_return = self.poke(context)
  File "/home/airflow/.local/lib/python3.8/site-packages/airflow/providers/http/sensors/http.py", line 132, in poke
    response = hook.run(
  File "/home/airflow/.local/lib/python3.8/site-packages/airflow/providers/http/hooks/http.py", line 166, in run
    return self.run_and_check(session, prepped_request, extra_options)
  File "/home/airflow/.local/lib/python3.8/site-packages/airflow/providers/http/hooks/http.py", line 222, in run_and_check
    raise ex
  File "/home/airflow/.local/lib/python3.8/site-packages/airflow/providers/http/hooks/http.py", line 214, in run_and_check
    response = session.send(prepped_request, **send_kwargs)
  File "/home/airflow/.local/lib/python3.8/site-packages/requests/sessions.py", line 703, in send
    r = adapter.send(request, **kwargs)
  File "/home/airflow/.local/lib/python3.8/site-packages/requests/adapters.py", line 519, in send
    raise ConnectionError(e, request=request)
requests.exceptions.ConnectionError: HTTPSConnectionPool(host='seeking-alpha.p.rapidapi.com', port=443): Max retries exceeded with url: /symbols/get-financials?symbol=aapl&target_currency=USD&period_type=annual&statement_type=income-statement (Caused by NewConnectionError('<urllib3.connection.HTTPSConnection object at 0x7ff792bb86a0>: Failed to establish a new connection: [Errno -3] Temporary failure in name resolution'))
[2024-02-08T00:00:14.870+0000] {taskinstance.py:1400} INFO - Marking task as UP_FOR_RETRY. dag_id=calculating_gross_margin, task_id=checking_api_for_data, execution_date=20240207T000000, start_date=20240208T000004, end_date=20240208T000014
[2024-02-08T00:00:14.886+0000] {standard_task_runner.py:104} ERROR - Failed to execute job 188 for task checking_api_for_data (HTTPSConnectionPool(host='seeking-alpha.p.rapidapi.com', port=443): Max retries exceeded with url: /symbols/get-financials?symbol=aapl&target_currency=USD&period_type=annual&statement_type=income-statement (Caused by NewConnectionError('<urllib3.connection.HTTPSConnection object at 0x7ff792bb86a0>: Failed to establish a new connection: [Errno -3] Temporary failure in name resolution')); 8775)
[2024-02-08T00:00:14.935+0000] {local_task_job_runner.py:228} INFO - Task exited with return code 1
[2024-02-08T00:00:14.957+0000] {taskinstance.py:2778} INFO - 0 downstream tasks scheduled from follow-on schedule check
