[2024-01-06T19:53:58.268+0000] {taskinstance.py:1159} INFO - Dependencies all met for dep_context=non-requeueable deps ti=<TaskInstance: downloading_fundamentals.downloading_fundamentals manual__2024-01-06T19:48:54.112637+00:00 [queued]>
[2024-01-06T19:53:58.289+0000] {taskinstance.py:1159} INFO - Dependencies all met for dep_context=requeueable deps ti=<TaskInstance: downloading_fundamentals.downloading_fundamentals manual__2024-01-06T19:48:54.112637+00:00 [queued]>
[2024-01-06T19:53:58.290+0000] {taskinstance.py:1361} INFO - Starting attempt 2 of 2
[2024-01-06T19:53:58.320+0000] {taskinstance.py:1382} INFO - Executing <Task(PythonOperator): downloading_fundamentals> on 2024-01-06 19:48:54.112637+00:00
[2024-01-06T19:53:58.333+0000] {standard_task_runner.py:57} INFO - Started process 158 to run task
[2024-01-06T19:53:58.339+0000] {standard_task_runner.py:84} INFO - Running: ['***', 'tasks', 'run', 'downloading_fundamentals', 'downloading_fundamentals', 'manual__2024-01-06T19:48:54.112637+00:00', '--job-id', '10', '--raw', '--subdir', 'DAGS_FOLDER/fundamental_data_pipeline.py', '--cfg-path', '/tmp/tmpjn8gjx4j']
[2024-01-06T19:53:58.347+0000] {standard_task_runner.py:85} INFO - Job 10: Subtask downloading_fundamentals
[2024-01-06T19:53:58.462+0000] {task_command.py:416} INFO - Running <TaskInstance: downloading_fundamentals.downloading_fundamentals manual__2024-01-06T19:48:54.112637+00:00 [running]> on host 028d52c20d97
[2024-01-06T19:53:58.544+0000] {taskinstance.py:1662} INFO - Exporting env vars: AIRFLOW_CTX_DAG_EMAIL='gerardchurch133@gmail.com' AIRFLOW_CTX_DAG_OWNER='Airflow' AIRFLOW_CTX_DAG_ID='downloading_fundamentals' AIRFLOW_CTX_TASK_ID='downloading_fundamentals' AIRFLOW_CTX_EXECUTION_DATE='2024-01-06T19:48:54.112637+00:00' AIRFLOW_CTX_TRY_NUMBER='2' AIRFLOW_CTX_DAG_RUN_ID='manual__2024-01-06T19:48:54.112637+00:00'
[2024-01-06T19:53:58.546+0000] {taskinstance.py:1937} ERROR - Task failed with exception
Traceback (most recent call last):
  File "/home/airflow/.local/lib/python3.8/site-packages/airflow/operators/python.py", line 192, in execute
    return_value = self.execute_callable()
  File "/home/airflow/.local/lib/python3.8/site-packages/airflow/operators/python.py", line 209, in execute_callable
    return self.python_callable(*self.op_args, **self.op_kwargs)
  File "/opt/airflow/dags/fundamental_data_pipeline.py", line 15, in get_fundamental_data
    headers = {"X-RapidAPI-Key": os.environ['rapidapi_key'],
  File "/usr/local/lib/python3.8/os.py", line 675, in __getitem__
    raise KeyError(key) from None
KeyError: 'rapidapi_key'
[2024-01-06T19:54:00.326+0000] {taskinstance.py:1400} INFO - Marking task as FAILED. dag_id=downloading_fundamentals, task_id=downloading_fundamentals, execution_date=20240106T194854, start_date=20240106T195358, end_date=20240106T195400
[2024-01-06T19:54:00.339+0000] {warnings.py:109} WARNING - /home/***/.local/lib/python3.8/site-packages/***/utils/email.py:154: RemovedInAirflow3Warning: Fetching SMTP credentials from configuration variables will be deprecated in a future release. Please set credentials using a connection instead.
  send_mime_email(e_from=mail_from, e_to=recipients, mime_msg=msg, conn_id=conn_id, dryrun=dryrun)

[2024-01-06T19:54:00.339+0000] {configuration.py:1050} WARNING - section/key [smtp/smtp_user] not found in config
[2024-01-06T19:54:00.340+0000] {email.py:270} INFO - Email alerting: attempt 1
[2024-01-06T19:54:00.348+0000] {configuration.py:1050} WARNING - section/key [smtp/smtp_user] not found in config
[2024-01-06T19:54:00.349+0000] {email.py:270} INFO - Email alerting: attempt 1
[2024-01-06T19:54:00.351+0000] {taskinstance.py:2007} ERROR - Failed to send email to: gerardchurch133@gmail.com
Traceback (most recent call last):
  File "/home/airflow/.local/lib/python3.8/site-packages/airflow/models/taskinstance.py", line 1518, in _run_raw_task
    self._execute_task_with_callbacks(context, test_mode, session=session)
  File "/home/airflow/.local/lib/python3.8/site-packages/airflow/models/taskinstance.py", line 1681, in _execute_task_with_callbacks
    result = self._execute_task(context, task_orig)
  File "/home/airflow/.local/lib/python3.8/site-packages/airflow/models/taskinstance.py", line 1744, in _execute_task
    result = execute_callable(context=context, **execute_callable_kwargs)
  File "/home/airflow/.local/lib/python3.8/site-packages/airflow/operators/python.py", line 192, in execute
    return_value = self.execute_callable()
  File "/home/airflow/.local/lib/python3.8/site-packages/airflow/operators/python.py", line 209, in execute_callable
    return self.python_callable(*self.op_args, **self.op_kwargs)
  File "/opt/airflow/dags/fundamental_data_pipeline.py", line 15, in get_fundamental_data
    headers = {"X-RapidAPI-Key": os.environ['rapidapi_key'],
  File "/usr/local/lib/python3.8/os.py", line 675, in __getitem__
    raise KeyError(key) from None
KeyError: 'rapidapi_key'

During handling of the above exception, another exception occurred:

Traceback (most recent call last):
  File "/home/airflow/.local/lib/python3.8/site-packages/airflow/models/taskinstance.py", line 2420, in email_alert
    send_email(task.email, subject, html_content)
  File "/home/airflow/.local/lib/python3.8/site-packages/airflow/utils/email.py", line 80, in send_email
    return backend(
  File "/home/airflow/.local/lib/python3.8/site-packages/airflow/utils/email.py", line 154, in send_email_smtp
    send_mime_email(e_from=mail_from, e_to=recipients, mime_msg=msg, conn_id=conn_id, dryrun=dryrun)
  File "/home/airflow/.local/lib/python3.8/site-packages/airflow/utils/email.py", line 272, in send_mime_email
    smtp_conn = _get_smtp_connection(smtp_host, smtp_port, smtp_timeout, smtp_ssl)
  File "/home/airflow/.local/lib/python3.8/site-packages/airflow/utils/email.py", line 316, in _get_smtp_connection
    return smtplib.SMTP(host=host, port=port, timeout=timeout)
  File "/usr/local/lib/python3.8/smtplib.py", line 255, in __init__
    (code, msg) = self.connect(host, port)
  File "/usr/local/lib/python3.8/smtplib.py", line 339, in connect
    self.sock = self._get_socket(host, port, self.timeout)
  File "/usr/local/lib/python3.8/smtplib.py", line 310, in _get_socket
    return socket.create_connection((host, port), timeout,
  File "/usr/local/lib/python3.8/socket.py", line 808, in create_connection
    raise err
  File "/usr/local/lib/python3.8/socket.py", line 796, in create_connection
    sock.connect(sa)
OSError: [Errno 99] Cannot assign requested address

During handling of the above exception, another exception occurred:

Traceback (most recent call last):
  File "/home/airflow/.local/lib/python3.8/site-packages/airflow/models/taskinstance.py", line 2005, in handle_failure
    self.email_alert(error, task)
  File "/home/airflow/.local/lib/python3.8/site-packages/airflow/models/taskinstance.py", line 2422, in email_alert
    send_email(task.email, subject, html_content_err)
  File "/home/airflow/.local/lib/python3.8/site-packages/airflow/utils/email.py", line 80, in send_email
    return backend(
  File "/home/airflow/.local/lib/python3.8/site-packages/airflow/utils/email.py", line 154, in send_email_smtp
    send_mime_email(e_from=mail_from, e_to=recipients, mime_msg=msg, conn_id=conn_id, dryrun=dryrun)
  File "/home/airflow/.local/lib/python3.8/site-packages/airflow/utils/email.py", line 272, in send_mime_email
    smtp_conn = _get_smtp_connection(smtp_host, smtp_port, smtp_timeout, smtp_ssl)
  File "/home/airflow/.local/lib/python3.8/site-packages/airflow/utils/email.py", line 316, in _get_smtp_connection
    return smtplib.SMTP(host=host, port=port, timeout=timeout)
  File "/usr/local/lib/python3.8/smtplib.py", line 255, in __init__
    (code, msg) = self.connect(host, port)
  File "/usr/local/lib/python3.8/smtplib.py", line 339, in connect
    self.sock = self._get_socket(host, port, self.timeout)
  File "/usr/local/lib/python3.8/smtplib.py", line 310, in _get_socket
    return socket.create_connection((host, port), timeout,
  File "/usr/local/lib/python3.8/socket.py", line 808, in create_connection
    raise err
  File "/usr/local/lib/python3.8/socket.py", line 796, in create_connection
    sock.connect(sa)
OSError: [Errno 99] Cannot assign requested address
[2024-01-06T19:54:00.367+0000] {standard_task_runner.py:104} ERROR - Failed to execute job 10 for task downloading_fundamentals ('rapidapi_key'; 158)
[2024-01-06T19:54:00.404+0000] {local_task_job_runner.py:228} INFO - Task exited with return code 1
[2024-01-06T19:54:00.421+0000] {taskinstance.py:2778} INFO - 0 downstream tasks scheduled from follow-on schedule check
