[2024-01-28T15:00:52.963+0000] {taskinstance.py:1159} INFO - Dependencies all met for dep_context=non-requeueable deps ti=<TaskInstance: downloading_fundamentals.downloading_fundamentals manual__2024-01-28T14:55:24.672014+00:00 [queued]>
[2024-01-28T15:00:52.971+0000] {taskinstance.py:1159} INFO - Dependencies all met for dep_context=requeueable deps ti=<TaskInstance: downloading_fundamentals.downloading_fundamentals manual__2024-01-28T14:55:24.672014+00:00 [queued]>
[2024-01-28T15:00:52.972+0000] {taskinstance.py:1361} INFO - Starting attempt 2 of 2
[2024-01-28T15:00:52.985+0000] {taskinstance.py:1382} INFO - Executing <Task(PythonOperator): downloading_fundamentals> on 2024-01-28 14:55:24.672014+00:00
[2024-01-28T15:00:53.005+0000] {standard_task_runner.py:57} INFO - Started process 72 to run task
[2024-01-28T15:00:53.008+0000] {standard_task_runner.py:84} INFO - Running: ['***', 'tasks', 'run', 'downloading_fundamentals', 'downloading_fundamentals', 'manual__2024-01-28T14:55:24.672014+00:00', '--job-id', '27', '--raw', '--subdir', 'DAGS_FOLDER/fundamental_data_pipeline.py', '--cfg-path', '/tmp/tmpkaukhq6a']
[2024-01-28T15:00:53.013+0000] {standard_task_runner.py:85} INFO - Job 27: Subtask downloading_fundamentals
[2024-01-28T15:00:53.068+0000] {task_command.py:416} INFO - Running <TaskInstance: downloading_fundamentals.downloading_fundamentals manual__2024-01-28T14:55:24.672014+00:00 [running]> on host 9188b4dc4885
[2024-01-28T15:00:53.148+0000] {taskinstance.py:1662} INFO - Exporting env vars: AIRFLOW_CTX_DAG_EMAIL='gerardchurch133@gmail.com' AIRFLOW_CTX_DAG_OWNER='Airflow' AIRFLOW_CTX_DAG_ID='downloading_fundamentals' AIRFLOW_CTX_TASK_ID='downloading_fundamentals' AIRFLOW_CTX_EXECUTION_DATE='2024-01-28T14:55:24.672014+00:00' AIRFLOW_CTX_TRY_NUMBER='2' AIRFLOW_CTX_DAG_RUN_ID='manual__2024-01-28T14:55:24.672014+00:00'
[2024-01-28T15:00:56.439+0000] {_universal.py:511} INFO - Request URL: 'https://datalakeuksouth2311.table.core.windows.net/fundamentalsraw/fundamentalsraw'
Request method: 'POST'
Request headers:
    'Content-Type': 'application/json;odata=nometadata'
    'Content-Length': '18176'
    'x-ms-version': 'REDACTED'
    'DataServiceVersion': 'REDACTED'
    'Accept': 'application/json;odata=minimalmetadata'
    'x-ms-client-request-id': '0a19a55e-bdee-11ee-a5cc-0242ac140004'
    'x-ms-date': 'REDACTED'
    'Date': 'Sun, 28 Jan 2024 15:00:56 GMT'
    'User-Agent': 'azsdk-python-data-tables/12.5.0 Python/3.8.18 (Linux-5.10.16.3-microsoft-standard-WSL2-x86_64-with-glibc2.2.5)'
    'Authorization': 'REDACTED'
A body is sent with the request
[2024-01-28T15:00:56.702+0000] {_universal.py:550} INFO - Response status: 409
Response headers:
    'Cache-Control': 'no-cache'
    'Transfer-Encoding': 'chunked'
    'Content-Type': 'application/json;odata=minimalmetadata;streaming=true;charset=utf-8'
    'Server': 'Windows-Azure-Table/1.0 Microsoft-HTTPAPI/2.0'
    'x-ms-request-id': 'a256bfbc-3002-005e-26fa-516bce000000'
    'x-ms-client-request-id': '0a19a55e-bdee-11ee-a5cc-0242ac140004'
    'x-ms-version': 'REDACTED'
    'X-Content-Type-Options': 'REDACTED'
    'Date': 'Sun, 28 Jan 2024 15:00:56 GMT'
[2024-01-28T15:00:56.706+0000] {taskinstance.py:1937} ERROR - Task failed with exception
Traceback (most recent call last):
  File "/home/airflow/.local/lib/python3.8/site-packages/airflow/operators/python.py", line 192, in execute
    return_value = self.execute_callable()
  File "/home/airflow/.local/lib/python3.8/site-packages/airflow/operators/python.py", line 209, in execute_callable
    return self.python_callable(*self.op_args, **self.op_kwargs)
  File "/opt/airflow/dags/fundamental_data_pipeline.py", line 50, in get_fundamental_data
    [fundamentals_raw_table.create_entity(entity) for entity in entities]
  File "/opt/airflow/dags/fundamental_data_pipeline.py", line 50, in <listcomp>
    [fundamentals_raw_table.create_entity(entity) for entity in entities]
  File "/home/airflow/.local/lib/python3.8/site-packages/azure/core/tracing/decorator.py", line 78, in wrapper_use_tracer
    return func(*args, **kwargs)
  File "/home/airflow/.local/lib/python3.8/site-packages/azure/data/tables/_table_client.py", line 405, in create_entity
    raise error
  File "/home/airflow/.local/lib/python3.8/site-packages/azure/data/tables/_table_client.py", line 393, in create_entity
    self._client.table.insert_entity(
  File "/home/airflow/.local/lib/python3.8/site-packages/azure/core/tracing/decorator.py", line 78, in wrapper_use_tracer
    return func(*args, **kwargs)
  File "/home/airflow/.local/lib/python3.8/site-packages/azure/data/tables/_generated/operations/_operations.py", line 1703, in insert_entity
    map_error(status_code=response.status_code, response=response, error_map=error_map)
  File "/home/airflow/.local/lib/python3.8/site-packages/azure/core/exceptions.py", line 165, in map_error
    raise error
azure.core.exceptions.ResourceExistsError: Operation returned an invalid status 'Conflict'
Content: {"odata.error":{"code":"EntityAlreadyExists","message":{"lang":"en-US","value":"The specified entity already exists.\nRequestId:a256bfbc-3002-005e-26fa-516bce000000\nTime:2024-01-28T15:00:57.2065590Z"}}}
[2024-01-28T15:00:56.723+0000] {taskinstance.py:1400} INFO - Marking task as FAILED. dag_id=downloading_fundamentals, task_id=downloading_fundamentals, execution_date=20240128T145524, start_date=20240128T150052, end_date=20240128T150056
[2024-01-28T15:00:56.737+0000] {warnings.py:109} WARNING - /home/***/.local/lib/python3.8/site-packages/***/utils/email.py:154: RemovedInAirflow3Warning: Fetching SMTP credentials from configuration variables will be deprecated in a future release. Please set credentials using a connection instead.
  send_mime_email(e_from=mail_from, e_to=recipients, mime_msg=msg, conn_id=conn_id, dryrun=dryrun)

[2024-01-28T15:00:56.738+0000] {configuration.py:1050} WARNING - section/key [smtp/smtp_user] not found in config
[2024-01-28T15:00:56.738+0000] {email.py:270} INFO - Email alerting: attempt 1
[2024-01-28T15:00:56.746+0000] {configuration.py:1050} WARNING - section/key [smtp/smtp_user] not found in config
[2024-01-28T15:00:56.747+0000] {email.py:270} INFO - Email alerting: attempt 1
[2024-01-28T15:00:56.748+0000] {taskinstance.py:2007} ERROR - Failed to send email to: gerardchurch133@gmail.com
Traceback (most recent call last):
  File "/home/airflow/.local/lib/python3.8/site-packages/airflow/models/taskinstance.py", line 1518, in _run_raw_task
    self._execute_task_with_callbacks(context, test_mode, session=session)
  File "/home/airflow/.local/lib/python3.8/site-packages/airflow/models/taskinstance.py", line 1681, in _execute_task_with_callbacks
    result = self._execute_task(context, task_orig)
  File "/home/airflow/.local/lib/python3.8/site-packages/airflow/models/taskinstance.py", line 1744, in _execute_task
    result = execute_callable(context=context, **execute_callable_kwargs)
  File "/home/airflow/.local/lib/python3.8/site-packages/airflow/operators/python.py", line 192, in execute
    return_value = self.execute_callable()
  File "/home/airflow/.local/lib/python3.8/site-packages/airflow/operators/python.py", line 209, in execute_callable
    return self.python_callable(*self.op_args, **self.op_kwargs)
  File "/opt/airflow/dags/fundamental_data_pipeline.py", line 50, in get_fundamental_data
    [fundamentals_raw_table.create_entity(entity) for entity in entities]
  File "/opt/airflow/dags/fundamental_data_pipeline.py", line 50, in <listcomp>
    [fundamentals_raw_table.create_entity(entity) for entity in entities]
  File "/home/airflow/.local/lib/python3.8/site-packages/azure/core/tracing/decorator.py", line 78, in wrapper_use_tracer
    return func(*args, **kwargs)
  File "/home/airflow/.local/lib/python3.8/site-packages/azure/data/tables/_table_client.py", line 405, in create_entity
    raise error
  File "/home/airflow/.local/lib/python3.8/site-packages/azure/data/tables/_table_client.py", line 393, in create_entity
    self._client.table.insert_entity(
  File "/home/airflow/.local/lib/python3.8/site-packages/azure/core/tracing/decorator.py", line 78, in wrapper_use_tracer
    return func(*args, **kwargs)
  File "/home/airflow/.local/lib/python3.8/site-packages/azure/data/tables/_generated/operations/_operations.py", line 1703, in insert_entity
    map_error(status_code=response.status_code, response=response, error_map=error_map)
  File "/home/airflow/.local/lib/python3.8/site-packages/azure/core/exceptions.py", line 165, in map_error
    raise error
azure.core.exceptions.ResourceExistsError: Operation returned an invalid status 'Conflict'
Content: {"odata.error":{"code":"EntityAlreadyExists","message":{"lang":"en-US","value":"The specified entity already exists.\nRequestId:a256bfbc-3002-005e-26fa-516bce000000\nTime:2024-01-28T15:00:57.2065590Z"}}}

During handling of the above exception, another exception occurred:

Traceback (most recent call last):
  File "/home/airflow/.local/lib/python3.8/site-packages/airflow/models/taskinstance.py", line 2420, in email_alert
    send_email(task.email, subject, html_content)
  File "/home/airflow/.local/lib/python3.8/site-packages/airflow/utils/email.py", line 80, in send_email
    return backend(
  File "/home/airflow/.local/lib/python3.8/site-packages/airflow/utils/email.py", line 154, in send_email_smtp
    send_mime_email(e_from=mail_from, e_to=recipients, mime_msg=msg, conn_id=conn_id, dryrun=dryrun)
  File "/home/airflow/.local/lib/python3.8/site-packages/airflow/utils/email.py", line 272, in send_mime_email
    smtp_conn = _get_smtp_connection(smtp_host, smtp_port, smtp_timeout, smtp_ssl)
  File "/home/airflow/.local/lib/python3.8/site-packages/airflow/utils/email.py", line 316, in _get_smtp_connection
    return smtplib.SMTP(host=host, port=port, timeout=timeout)
  File "/usr/local/lib/python3.8/smtplib.py", line 255, in __init__
    (code, msg) = self.connect(host, port)
  File "/usr/local/lib/python3.8/smtplib.py", line 339, in connect
    self.sock = self._get_socket(host, port, self.timeout)
  File "/usr/local/lib/python3.8/smtplib.py", line 310, in _get_socket
    return socket.create_connection((host, port), timeout,
  File "/usr/local/lib/python3.8/socket.py", line 808, in create_connection
    raise err
  File "/usr/local/lib/python3.8/socket.py", line 796, in create_connection
    sock.connect(sa)
OSError: [Errno 99] Cannot assign requested address

During handling of the above exception, another exception occurred:

Traceback (most recent call last):
  File "/home/airflow/.local/lib/python3.8/site-packages/airflow/models/taskinstance.py", line 2005, in handle_failure
    self.email_alert(error, task)
  File "/home/airflow/.local/lib/python3.8/site-packages/airflow/models/taskinstance.py", line 2422, in email_alert
    send_email(task.email, subject, html_content_err)
  File "/home/airflow/.local/lib/python3.8/site-packages/airflow/utils/email.py", line 80, in send_email
    return backend(
  File "/home/airflow/.local/lib/python3.8/site-packages/airflow/utils/email.py", line 154, in send_email_smtp
    send_mime_email(e_from=mail_from, e_to=recipients, mime_msg=msg, conn_id=conn_id, dryrun=dryrun)
  File "/home/airflow/.local/lib/python3.8/site-packages/airflow/utils/email.py", line 272, in send_mime_email
    smtp_conn = _get_smtp_connection(smtp_host, smtp_port, smtp_timeout, smtp_ssl)
  File "/home/airflow/.local/lib/python3.8/site-packages/airflow/utils/email.py", line 316, in _get_smtp_connection
    return smtplib.SMTP(host=host, port=port, timeout=timeout)
  File "/usr/local/lib/python3.8/smtplib.py", line 255, in __init__
    (code, msg) = self.connect(host, port)
  File "/usr/local/lib/python3.8/smtplib.py", line 339, in connect
    self.sock = self._get_socket(host, port, self.timeout)
  File "/usr/local/lib/python3.8/smtplib.py", line 310, in _get_socket
    return socket.create_connection((host, port), timeout,
  File "/usr/local/lib/python3.8/socket.py", line 808, in create_connection
    raise err
  File "/usr/local/lib/python3.8/socket.py", line 796, in create_connection
    sock.connect(sa)
OSError: [Errno 99] Cannot assign requested address
[2024-01-28T15:00:56.765+0000] {standard_task_runner.py:104} ERROR - Failed to execute job 27 for task downloading_fundamentals (Operation returned an invalid status 'Conflict'
Content: {"odata.error":{"code":"EntityAlreadyExists","message":{"lang":"en-US","value":"The specified entity already exists.\nRequestId:a256bfbc-3002-005e-26fa-516bce000000\nTime:2024-01-28T15:00:57.2065590Z"}}}; 72)
[2024-01-28T15:00:56.793+0000] {local_task_job_runner.py:228} INFO - Task exited with return code 1
[2024-01-28T15:00:56.810+0000] {taskinstance.py:2778} INFO - 0 downstream tasks scheduled from follow-on schedule check
