[2024-01-29T21:32:37.831+0000] {taskinstance.py:1159} INFO - Dependencies all met for dep_context=non-requeueable deps ti=<TaskInstance: downloading_fundamentals.wait_for_api manual__2024-01-29T21:32:35.817615+00:00 [queued]>
[2024-01-29T21:32:37.839+0000] {taskinstance.py:1159} INFO - Dependencies all met for dep_context=requeueable deps ti=<TaskInstance: downloading_fundamentals.wait_for_api manual__2024-01-29T21:32:35.817615+00:00 [queued]>
[2024-01-29T21:32:37.840+0000] {taskinstance.py:1361} INFO - Starting attempt 1 of 2
[2024-01-29T21:32:37.858+0000] {taskinstance.py:1382} INFO - Executing <Task(HttpSensor): wait_for_api> on 2024-01-29 21:32:35.817615+00:00
[2024-01-29T21:32:37.865+0000] {standard_task_runner.py:57} INFO - Started process 535 to run task
[2024-01-29T21:32:37.869+0000] {standard_task_runner.py:84} INFO - Running: ['***', 'tasks', 'run', 'downloading_fundamentals', 'wait_for_api', 'manual__2024-01-29T21:32:35.817615+00:00', '--job-id', '52', '--raw', '--subdir', 'DAGS_FOLDER/fundamental_data_pipeline.py', '--cfg-path', '/tmp/tmpqqn5tza5']
[2024-01-29T21:32:37.873+0000] {standard_task_runner.py:85} INFO - Job 52: Subtask wait_for_api
[2024-01-29T21:32:37.932+0000] {task_command.py:416} INFO - Running <TaskInstance: downloading_fundamentals.wait_for_api manual__2024-01-29T21:32:35.817615+00:00 [running]> on host 77ce723575d8
[2024-01-29T21:32:38.010+0000] {taskinstance.py:1662} INFO - Exporting env vars: AIRFLOW_CTX_DAG_EMAIL='gerardchurch133@gmail.com' AIRFLOW_CTX_DAG_OWNER='Airflow' AIRFLOW_CTX_DAG_ID='downloading_fundamentals' AIRFLOW_CTX_TASK_ID='wait_for_api' AIRFLOW_CTX_EXECUTION_DATE='2024-01-29T21:32:35.817615+00:00' AIRFLOW_CTX_TRY_NUMBER='1' AIRFLOW_CTX_DAG_RUN_ID='manual__2024-01-29T21:32:35.817615+00:00'
[2024-01-29T21:32:38.011+0000] {http.py:130} INFO - Poking: symbols/get-financials
[2024-01-29T21:32:38.019+0000] {base.py:73} INFO - Using connection ID 'rapid_api' for task execution.
[2024-01-29T21:32:41.469+0000] {http.py:178} ERROR - HTTP error: Unauthorized
[2024-01-29T21:32:41.470+0000] {http.py:179} ERROR - {"message":"Invalid API key. Go to https:\/\/docs.rapidapi.com\/docs\/keys for more info."}
[2024-01-29T21:32:41.478+0000] {taskinstance.py:1937} ERROR - Task failed with exception
Traceback (most recent call last):
  File "/home/airflow/.local/lib/python3.8/site-packages/airflow/providers/http/hooks/http.py", line 176, in check_response
    response.raise_for_status()
  File "/home/airflow/.local/lib/python3.8/site-packages/requests/models.py", line 1021, in raise_for_status
    raise HTTPError(http_error_msg, response=self)
requests.exceptions.HTTPError: 401 Client Error: Unauthorized for url: https://seeking-alpha.p.rapidapi.com/symbols/get-financials

During handling of the above exception, another exception occurred:

Traceback (most recent call last):
  File "/home/airflow/.local/lib/python3.8/site-packages/airflow/sensors/base.py", line 257, in execute
    raise e
  File "/home/airflow/.local/lib/python3.8/site-packages/airflow/sensors/base.py", line 239, in execute
    poke_return = self.poke(context)
  File "/home/airflow/.local/lib/python3.8/site-packages/airflow/providers/http/sensors/http.py", line 148, in poke
    raise exc
  File "/home/airflow/.local/lib/python3.8/site-packages/airflow/providers/http/sensors/http.py", line 132, in poke
    response = hook.run(
  File "/home/airflow/.local/lib/python3.8/site-packages/airflow/providers/http/hooks/http.py", line 166, in run
    return self.run_and_check(session, prepped_request, extra_options)
  File "/home/airflow/.local/lib/python3.8/site-packages/airflow/providers/http/hooks/http.py", line 217, in run_and_check
    self.check_response(response)
  File "/home/airflow/.local/lib/python3.8/site-packages/airflow/providers/http/hooks/http.py", line 180, in check_response
    raise AirflowException(str(response.status_code) + ":" + response.reason)
airflow.exceptions.AirflowException: 401:Unauthorized
[2024-01-29T21:32:41.527+0000] {taskinstance.py:1400} INFO - Marking task as UP_FOR_RETRY. dag_id=downloading_fundamentals, task_id=wait_for_api, execution_date=20240129T213235, start_date=20240129T213237, end_date=20240129T213241
[2024-01-29T21:32:41.556+0000] {standard_task_runner.py:104} ERROR - Failed to execute job 52 for task wait_for_api (401:Unauthorized; 535)
[2024-01-29T21:32:41.576+0000] {local_task_job_runner.py:228} INFO - Task exited with return code 1
[2024-01-29T21:32:41.602+0000] {taskinstance.py:2778} INFO - 0 downstream tasks scheduled from follow-on schedule check
