[2024-01-29T22:38:39.208+0000] {taskinstance.py:1159} INFO - Dependencies all met for dep_context=non-requeueable deps ti=<TaskInstance: downloading_fundamentals.wait_for_api manual__2024-01-29T22:37:13.952847+00:00 [queued]>
[2024-01-29T22:38:39.217+0000] {taskinstance.py:1159} INFO - Dependencies all met for dep_context=requeueable deps ti=<TaskInstance: downloading_fundamentals.wait_for_api manual__2024-01-29T22:37:13.952847+00:00 [queued]>
[2024-01-29T22:38:39.217+0000] {taskinstance.py:1361} INFO - Starting attempt 1 of 2
[2024-01-29T22:38:39.239+0000] {taskinstance.py:1382} INFO - Executing <Task(HttpSensor): wait_for_api> on 2024-01-29 22:37:13.952847+00:00
[2024-01-29T22:38:39.283+0000] {standard_task_runner.py:57} INFO - Started process 519 to run task
[2024-01-29T22:38:39.311+0000] {standard_task_runner.py:84} INFO - Running: ['***', 'tasks', 'run', 'downloading_fundamentals', 'wait_for_api', 'manual__2024-01-29T22:37:13.952847+00:00', '--job-id', '59', '--raw', '--subdir', 'DAGS_FOLDER/fundamental_data_pipeline.py', '--cfg-path', '/tmp/tmpkhhevh8m']
[2024-01-29T22:38:39.318+0000] {standard_task_runner.py:85} INFO - Job 59: Subtask wait_for_api
[2024-01-29T22:38:41.800+0000] {task_command.py:416} INFO - Running <TaskInstance: downloading_fundamentals.wait_for_api manual__2024-01-29T22:37:13.952847+00:00 [running]> on host f0a0590a9ae4
[2024-01-29T22:38:42.489+0000] {taskinstance.py:1662} INFO - Exporting env vars: AIRFLOW_CTX_DAG_EMAIL='gerardchurch133@gmail.com' AIRFLOW_CTX_DAG_OWNER='Airflow' AIRFLOW_CTX_DAG_ID='downloading_fundamentals' AIRFLOW_CTX_TASK_ID='wait_for_api' AIRFLOW_CTX_EXECUTION_DATE='2024-01-29T22:37:13.952847+00:00' AIRFLOW_CTX_TRY_NUMBER='1' AIRFLOW_CTX_DAG_RUN_ID='manual__2024-01-29T22:37:13.952847+00:00'
[2024-01-29T22:38:42.497+0000] {http.py:130} INFO - Poking: symbols/get-financials
[2024-01-29T22:38:43.283+0000] {base.py:73} INFO - Using connection ID 'rapid_api' for task execution.
[2024-01-29T22:39:51.878+0000] {http.py:130} INFO - Poking: symbols/get-financials
[2024-01-29T22:39:51.885+0000] {base.py:73} INFO - Using connection ID 'rapid_api' for task execution.
[2024-01-29T22:40:52.521+0000] {http.py:130} INFO - Poking: symbols/get-financials
[2024-01-29T22:40:52.532+0000] {base.py:73} INFO - Using connection ID 'rapid_api' for task execution.
[2024-01-29T22:41:53.281+0000] {http.py:130} INFO - Poking: symbols/get-financials
[2024-01-29T22:41:53.289+0000] {base.py:73} INFO - Using connection ID 'rapid_api' for task execution.
[2024-01-29T22:42:53.811+0000] {http.py:130} INFO - Poking: symbols/get-financials
[2024-01-29T22:42:53.819+0000] {base.py:73} INFO - Using connection ID 'rapid_api' for task execution.
[2024-01-29T22:43:54.428+0000] {http.py:130} INFO - Poking: symbols/get-financials
[2024-01-29T22:43:54.439+0000] {base.py:73} INFO - Using connection ID 'rapid_api' for task execution.
[2024-01-29T22:43:55.007+0000] {taskinstance.py:1937} ERROR - Task failed with exception
Traceback (most recent call last):
  File "/home/airflow/.local/lib/python3.8/site-packages/airflow/sensors/base.py", line 274, in execute
    raise AirflowSensorTimeout(message)
airflow.exceptions.AirflowSensorTimeout: Sensor has timed out; run duration of 312.4766660000023 seconds exceeds the specified timeout of 300.0.
[2024-01-29T22:43:55.229+0000] {taskinstance.py:1400} INFO - Immediate failure requested. Marking task as FAILED. dag_id=downloading_fundamentals, task_id=wait_for_api, execution_date=20240129T223713, start_date=20240129T223839, end_date=20240129T224355
[2024-01-29T22:43:55.350+0000] {warnings.py:109} WARNING - /home/***/.local/lib/python3.8/site-packages/***/utils/email.py:154: RemovedInAirflow3Warning: Fetching SMTP credentials from configuration variables will be deprecated in a future release. Please set credentials using a connection instead.
  send_mime_email(e_from=mail_from, e_to=recipients, mime_msg=msg, conn_id=conn_id, dryrun=dryrun)

[2024-01-29T22:43:55.352+0000] {configuration.py:1050} WARNING - section/key [smtp/smtp_user] not found in config
[2024-01-29T22:43:55.353+0000] {email.py:270} INFO - Email alerting: attempt 1
[2024-01-29T22:43:55.362+0000] {configuration.py:1050} WARNING - section/key [smtp/smtp_user] not found in config
[2024-01-29T22:43:55.363+0000] {email.py:270} INFO - Email alerting: attempt 1
[2024-01-29T22:43:55.363+0000] {taskinstance.py:2007} ERROR - Failed to send email to: gerardchurch133@gmail.com
Traceback (most recent call last):
  File "/home/airflow/.local/lib/python3.8/site-packages/airflow/models/taskinstance.py", line 1518, in _run_raw_task
    self._execute_task_with_callbacks(context, test_mode, session=session)
  File "/home/airflow/.local/lib/python3.8/site-packages/airflow/models/taskinstance.py", line 1681, in _execute_task_with_callbacks
    result = self._execute_task(context, task_orig)
  File "/home/airflow/.local/lib/python3.8/site-packages/airflow/models/taskinstance.py", line 1744, in _execute_task
    result = execute_callable(context=context, **execute_callable_kwargs)
  File "/home/airflow/.local/lib/python3.8/site-packages/airflow/sensors/base.py", line 274, in execute
    raise AirflowSensorTimeout(message)
airflow.exceptions.AirflowSensorTimeout: Sensor has timed out; run duration of 312.4766660000023 seconds exceeds the specified timeout of 300.0.

During handling of the above exception, another exception occurred:

Traceback (most recent call last):
  File "/home/airflow/.local/lib/python3.8/site-packages/airflow/models/taskinstance.py", line 2420, in email_alert
    send_email(task.email, subject, html_content)
  File "/home/airflow/.local/lib/python3.8/site-packages/airflow/utils/email.py", line 80, in send_email
    return backend(
  File "/home/airflow/.local/lib/python3.8/site-packages/airflow/utils/email.py", line 154, in send_email_smtp
    send_mime_email(e_from=mail_from, e_to=recipients, mime_msg=msg, conn_id=conn_id, dryrun=dryrun)
  File "/home/airflow/.local/lib/python3.8/site-packages/airflow/utils/email.py", line 272, in send_mime_email
    smtp_conn = _get_smtp_connection(smtp_host, smtp_port, smtp_timeout, smtp_ssl)
  File "/home/airflow/.local/lib/python3.8/site-packages/airflow/utils/email.py", line 316, in _get_smtp_connection
    return smtplib.SMTP(host=host, port=port, timeout=timeout)
  File "/usr/local/lib/python3.8/smtplib.py", line 255, in __init__
    (code, msg) = self.connect(host, port)
  File "/usr/local/lib/python3.8/smtplib.py", line 339, in connect
    self.sock = self._get_socket(host, port, self.timeout)
  File "/usr/local/lib/python3.8/smtplib.py", line 310, in _get_socket
    return socket.create_connection((host, port), timeout,
  File "/usr/local/lib/python3.8/socket.py", line 808, in create_connection
    raise err
  File "/usr/local/lib/python3.8/socket.py", line 796, in create_connection
    sock.connect(sa)
OSError: [Errno 99] Cannot assign requested address

During handling of the above exception, another exception occurred:

Traceback (most recent call last):
  File "/home/airflow/.local/lib/python3.8/site-packages/airflow/models/taskinstance.py", line 2005, in handle_failure
    self.email_alert(error, task)
  File "/home/airflow/.local/lib/python3.8/site-packages/airflow/models/taskinstance.py", line 2422, in email_alert
    send_email(task.email, subject, html_content_err)
  File "/home/airflow/.local/lib/python3.8/site-packages/airflow/utils/email.py", line 80, in send_email
    return backend(
  File "/home/airflow/.local/lib/python3.8/site-packages/airflow/utils/email.py", line 154, in send_email_smtp
    send_mime_email(e_from=mail_from, e_to=recipients, mime_msg=msg, conn_id=conn_id, dryrun=dryrun)
  File "/home/airflow/.local/lib/python3.8/site-packages/airflow/utils/email.py", line 272, in send_mime_email
    smtp_conn = _get_smtp_connection(smtp_host, smtp_port, smtp_timeout, smtp_ssl)
  File "/home/airflow/.local/lib/python3.8/site-packages/airflow/utils/email.py", line 316, in _get_smtp_connection
    return smtplib.SMTP(host=host, port=port, timeout=timeout)
  File "/usr/local/lib/python3.8/smtplib.py", line 255, in __init__
    (code, msg) = self.connect(host, port)
  File "/usr/local/lib/python3.8/smtplib.py", line 339, in connect
    self.sock = self._get_socket(host, port, self.timeout)
  File "/usr/local/lib/python3.8/smtplib.py", line 310, in _get_socket
    return socket.create_connection((host, port), timeout,
  File "/usr/local/lib/python3.8/socket.py", line 808, in create_connection
    raise err
  File "/usr/local/lib/python3.8/socket.py", line 796, in create_connection
    sock.connect(sa)
OSError: [Errno 99] Cannot assign requested address
[2024-01-29T22:43:55.534+0000] {standard_task_runner.py:104} ERROR - Failed to execute job 59 for task wait_for_api (Sensor has timed out; run duration of 312.4766660000023 seconds exceeds the specified timeout of 300.0.; 519)
[2024-01-29T22:43:55.625+0000] {local_task_job_runner.py:228} INFO - Task exited with return code 1
[2024-01-29T22:43:55.998+0000] {taskinstance.py:2778} INFO - 0 downstream tasks scheduled from follow-on schedule check
